<?xml version="1.0" ?>
<!-- =================================================================================== -->
<!-- |    This document was autogenerated by xacro from /home/sanchit/catkin_ws/src/robotic_arm_description/robotic_arm_description/urdf/robotic_arm.xacro | -->
<!-- |    EDITING THIS FILE BY HAND IS NOT RECOMMENDED                                 | -->
<!-- =================================================================================== -->
<robot name="robotic_arm">
    <material name="silver">
        <color rgba="0.700 0.700 0.700 1.000" />
    </material>
    <transmission name="Revolute_12_tran">
        <type>transmission_interface/SimpleTransmission</type>
        <joint name="Revolute_12">
            <hardwareInterface>hardware_interface/EffortJointInterface</hardwareInterface>
        </joint>
        <actuator name="Revolute_12_actr">
            <hardwareInterface>hardware_interface/EffortJointInterface</hardwareInterface>
            <mechanicalReduction>1</mechanicalReduction>
        </actuator>
    </transmission>
    <transmission name="Revolute_13_tran">
        <type>transmission_interface/SimpleTransmission</type>
        <joint name="Revolute_13">
            <hardwareInterface>hardware_interface/EffortJointInterface</hardwareInterface>
        </joint>
        <actuator name="Revolute_13_actr">
            <hardwareInterface>hardware_interface/EffortJointInterface</hardwareInterface>
            <mechanicalReduction>1</mechanicalReduction>
        </actuator>
    </transmission>
    <transmission name="Revolute_14_tran">
        <type>transmission_interface/SimpleTransmission</type>
        <joint name="Revolute_14">
            <hardwareInterface>hardware_interface/EffortJointInterface</hardwareInterface>
        </joint>
        <actuator name="Revolute_14_actr">
            <hardwareInterface>hardware_interface/EffortJointInterface</hardwareInterface>
            <mechanicalReduction>1</mechanicalReduction>
        </actuator>
    </transmission>
    <transmission name="Revolute_15_tran">
        <type>transmission_interface/SimpleTransmission</type>
        <joint name="Revolute_15">
            <hardwareInterface>hardware_interface/EffortJointInterface</hardwareInterface>
        </joint>
        <actuator name="Revolute_15_actr">
            <hardwareInterface>hardware_interface/EffortJointInterface</hardwareInterface>
            <mechanicalReduction>1</mechanicalReduction>
        </actuator>
    </transmission>
    <transmission name="Revolute_16_tran">
        <type>transmission_interface/SimpleTransmission</type>
        <joint name="Revolute_16">
            <hardwareInterface>hardware_interface/EffortJointInterface</hardwareInterface>
        </joint>
        <actuator name="Revolute_16_actr">
            <hardwareInterface>hardware_interface/EffortJointInterface</hardwareInterface>
            <mechanicalReduction>1</mechanicalReduction>
        </actuator>
    </transmission>
    <transmission name="Revolute_17_tran">
        <type>transmission_interface/SimpleTransmission</type>
        <joint name="Revolute_17">
            <hardwareInterface>hardware_interface/EffortJointInterface</hardwareInterface>
        </joint>
        <actuator name="Revolute_17_actr">
            <hardwareInterface>hardware_interface/EffortJointInterface</hardwareInterface>
            <mechanicalReduction>1</mechanicalReduction>
        </actuator>
    </transmission>
    <transmission name="Revolute_22_tran">
        <type>transmission_interface/SimpleTransmission</type>
        <joint name="Revolute_22">
            <hardwareInterface>hardware_interface/EffortJointInterface</hardwareInterface>
        </joint>
        <actuator name="Revolute_22_actr">
            <hardwareInterface>hardware_interface/EffortJointInterface</hardwareInterface>
            <mechanicalReduction>1</mechanicalReduction>
        </actuator>
    </transmission>
    <transmission name="Revolute_24_tran">
        <type>transmission_interface/SimpleTransmission</type>
        <joint name="Revolute_24">
            <hardwareInterface>hardware_interface/EffortJointInterface</hardwareInterface>
        </joint>
        <actuator name="Revolute_24_actr">
            <hardwareInterface>hardware_interface/EffortJointInterface</hardwareInterface>
            <mechanicalReduction>1</mechanicalReduction>
        </actuator>
    </transmission>
    <gazebo>
        <plugin filename="libgazebo_ros_control.so" name="control" />
        <plugin name="gazebo_ros_control" filename="libgazebo_ros_control.so">
            <robotNamespace>/</robotNamespace>
        </plugin>
    </gazebo>
    <gazebo reference="base_link">
        <material>Gazebo/Silver</material>
        <mu1>0.2</mu1>
        <mu2>0.2</mu2>
        <selfCollide>true</selfCollide>
        <gravity>true</gravity>
    </gazebo>
    <gazebo reference="jaw1_1">
        <material>Gazebo/Silver</material>
        <mu1>0.2</mu1>
        <mu2>0.2</mu2>
        <selfCollide>true</selfCollide>
    </gazebo>
    <gazebo reference="jaw2_1">
        <material>Gazebo/Silver</material>
        <mu1>0.2</mu1>
        <mu2>0.2</mu2>
        <selfCollide>true</selfCollide>
    </gazebo>
    <gazebo reference="jaw3_1">
        <material>Gazebo/Silver</material>
        <mu1>0.2</mu1>
        <mu2>0.2</mu2>
        <selfCollide>true</selfCollide>
    </gazebo>
    <gazebo reference="jaw4_1">
        <material>Gazebo/Silver</material>
        <mu1>0.2</mu1>
        <mu2>0.2</mu2>
        <selfCollide>true</selfCollide>
    </gazebo>
    <gazebo reference="jaw5_1">
        <material>Gazebo/Silver</material>
        <mu1>0.2</mu1>
        <mu2>0.2</mu2>
        <selfCollide>true</selfCollide>
    </gazebo>
    <gazebo reference="jaw6_1">
        <material>Gazebo/Silver</material>
        <mu1>0.2</mu1>
        <mu2>0.2</mu2>
        <selfCollide>true</selfCollide>
    </gazebo>
    <gazebo reference="jaw7.1_1">
        <material>Gazebo/Silver</material>
        <mu1>0.2</mu1>
        <mu2>0.2</mu2>
        <selfCollide>true</selfCollide>
    </gazebo>
    <gazebo reference="jaw7.2_1">
        <material>Gazebo/Silver</material>
        <mu1>0.2</mu1>
        <mu2>0.2</mu2>
        <selfCollide>true</selfCollide>
    </gazebo>
    <link name="world" />
    <joint name="base_joint" type="fixed">
        <parent link="world" />
        <child link="base_link" />
        <origin rpy="0 0 3.141592653589793" xyz="0.0 0.0 0.00" />
    </joint>
    <link name="base_link">
        <inertial>
            <origin rpy="0 0 0" xyz="0.001959497114940088 0.05978383996103833 0.03890078890987177" />
            <mass value="45.32032017365632" />
            <inertia ixx="0.286642" ixy="0.006277" ixz="-0.000324" iyy="0.286642" iyz="-0.000324" izz="0.523382" />
        </inertial>
        <visual>
            <origin rpy="0 0 0" xyz="0 0 0" />
            <geometry>
                <mesh filename="package://robotic_arm_description/meshes/base_link.stl" scale="0.001 0.001 0.001" />
            </geometry>
            <material name="silver" />
        </visual>
        <collision>
            <origin rpy="0 0 0" xyz="0 0 0" />
            <geometry>
                <mesh filename="package://robotic_arm_description/meshes/base_link.stl" scale="0.001 0.001 0.001" />
            </geometry>
        </collision>
    </link>
    <link name="jaw1_1">
        <inertial>
            <origin rpy="0 0 0" xyz="-0.05909431116233142 -0.004006139353276157 0.08486906818603877" />
            <mass value="18.786497279184598" />
            <inertia ixx="0.097516" ixy="-0.004893" ixz="0.074275" iyy="0.193949" iyz="0.004445" izz="0.13248" />
        </inertial>
        <visual>
            <origin rpy="0 0 0" xyz="-0.000534 -0.058358 -0.084193" />
            <geometry>
                <mesh filename="package://robotic_arm_description/meshes/jaw1_1.stl" scale="0.001 0.001 0.001" />
            </geometry>
            <material name="silver" />
        </visual>
        <collision>
            <origin rpy="0 0 0" xyz="-0.000534 -0.058358 -0.084193" />
            <geometry>
                <mesh filename="package://robotic_arm_description/meshes/jaw1_1.stl" scale="0.001 0.001 0.001" />
            </geometry>
        </collision>
    </link>
    <link name="jaw2_1">
        <inertial>
            <origin rpy="0 0 0" xyz="0.009396645752536514 0.016346673293803182 0.14982483184809242" />
            <mass value="8.268509087861013" />
            <inertia ixx="0.148718" ixy="0.000176" ixz="-0.001868" iyy="0.15176" iyz="0.000132" izz="0.005454" />
        </inertial>
        <visual>
            <origin rpy="0 0 0" xyz="0.149466 -0.078358 -0.244193" />
            <geometry>
                <mesh filename="package://robotic_arm_description/meshes/jaw2_1.stl" scale="0.001 0.001 0.001" />
            </geometry>
            <material name="silver" />
        </visual>
        <collision>
            <origin rpy="0 0 0" xyz="0.149466 -0.078358 -0.244193" />
            <geometry>
                <mesh filename="package://robotic_arm_description/meshes/jaw2_1.stl" scale="0.001 0.001 0.001" />
            </geometry>
        </collision>
    </link>
    <link name="jaw3_1">
        <inertial>
            <origin rpy="0 0 0" xyz="-0.0440646053080877 -0.04638873406015811 0.0386121340726453" />
            <mass value="11.356819633945126" />
            <inertia ixx="0.015087" ixy="-0.000806" ixz="0.002822" iyy="0.066371" iyz="0.000957" izz="0.063354" />
        </inertial>
        <visual>
            <origin rpy="0 0 0" xyz="0.149466 -0.078358 -0.594193" />
            <geometry>
                <mesh filename="package://robotic_arm_description/meshes/jaw3_1.stl" scale="0.001 0.001 0.001" />
            </geometry>
            <material name="silver" />
        </visual>
        <collision>
            <origin rpy="0 0 0" xyz="0.149466 -0.078358 -0.594193" />
            <geometry>
                <mesh filename="package://robotic_arm_description/meshes/jaw3_1.stl" scale="0.001 0.001 0.001" />
            </geometry>
        </collision>
    </link>
    <link name="jaw4_1">
        <inertial>
            <origin rpy="0 0 0" xyz="-0.06936002908715583 3.497152024183048e-07 -3.3635927376707286e-09" />
            <mass value="4.590924229482726" />
            <inertia ixx="0.004483" ixy="0.0" ixz="-0.0" iyy="0.010937" iyz="0.0" izz="0.012117" />
        </inertial>
        <visual>
            <origin rpy="0 0 0" xyz="0.395729 -0.030358 -0.638445" />
            <geometry>
                <mesh filename="package://robotic_arm_description/meshes/jaw4_1.stl" scale="0.001 0.001 0.001" />
            </geometry>
            <material name="silver" />
        </visual>
        <collision>
            <origin rpy="0 0 0" xyz="0.395729 -0.030358 -0.638445" />
            <geometry>
                <mesh filename="package://robotic_arm_description/meshes/jaw4_1.stl" scale="0.001 0.001 0.001" />
            </geometry>
        </collision>
    </link>
    <link name="jaw5_1">
        <inertial>
            <origin rpy="0 0 0" xyz="-0.05742274909820899 -0.012074329975050303 -1.3415845545594607e-08" />
            <mass value="2.620268703215457" />
            <inertia ixx="0.00186" ixy="8e-06" ixz="-0.0" iyy="0.002813" iyz="0.0" izz="0.002794" />
        </inertial>
        <visual>
            <origin rpy="0 0 0" xyz="0.510729 -0.042858 -0.638445" />
            <geometry>
                <mesh filename="package://robotic_arm_description/meshes/jaw5_1.stl" scale="0.001 0.001 0.001" />
            </geometry>
            <material name="silver" />
        </visual>
        <collision>
            <origin rpy="0 0 0" xyz="0.510729 -0.042858 -0.638445" />
            <geometry>
                <mesh filename="package://robotic_arm_description/meshes/jaw5_1.stl" scale="0.001 0.001 0.001" />
            </geometry>
        </collision>
    </link>
    <link name="jaw6_1">
        <inertial>
            <origin rpy="0 0 0" xyz="-0.01670255088998085 3.481973394128812e-07 1.54420520739329e-05" />
            <mass value="0.6134273281691381" />
            <inertia ixx="0.000336" ixy="0.0" ixz="0.0" iyy="0.000257" iyz="0.0" izz="0.000324" />
        </inertial>
        <visual>
            <origin rpy="0 0 0" xyz="0.603729 -0.030858 -0.638445" />
            <geometry>
                <mesh filename="package://robotic_arm_description/meshes/jaw6_1.stl" scale="0.001 0.001 0.001" />
            </geometry>
            <material name="silver" />
        </visual>
        <collision>
            <origin rpy="0 0 0" xyz="0.603729 -0.030858 -0.638445" />
            <geometry>
                <mesh filename="package://robotic_arm_description/meshes/jaw6_1.stl" scale="0.001 0.001 0.001" />
            </geometry>
        </collision>
    </link>
    <link name="jaw7.1_1">
        <inertial>
            <origin rpy="0 0 0" xyz="-0.04724180067561057 0.017982710949063882 -0.008596920840052924" />
            <mass value="0.17039946788074226" />
            <inertia ixx="2.9e-05" ixy="2.1e-05" ixz="0.0" iyy="0.000196" iyz="-0.0" izz="0.000219" />
        </inertial>
        <visual>
            <origin rpy="0 0 0" xyz="0.636621 -0.070168 -0.647445" />
            <geometry>
                <mesh filename="package://robotic_arm_description/meshes/jaw7.1_1.stl" scale="0.001 0.001 0.001" />
            </geometry>
            <material name="silver" />
        </visual>
        <collision>
            <origin rpy="0 0 0" xyz="0.636621 -0.070168 -0.647445" />
            <geometry>
                <mesh filename="package://robotic_arm_description/meshes/jaw7.1_1.stl" scale="0.001 0.001 0.001" />
            </geometry>
        </collision>
    </link>
    <link name="jaw7.2_1">
        <inertial>
            <origin rpy="0 0 0" xyz="-0.04724180067561157 -0.01798301455438199 -0.008596920840050148" />
            <mass value="0.17039946788074223" />
            <inertia ixx="2.9e-05" ixy="-2.1e-05" ixz="0.0" iyy="0.000196" iyz="0.0" izz="0.000219" />
        </inertial>
        <visual>
            <origin rpy="0 0 0" xyz="0.636621 0.008451 -0.647445" />
            <geometry>
                <mesh filename="package://robotic_arm_description/meshes/jaw7.2_1.stl" scale="0.001 0.001 0.001" />
            </geometry>
            <material name="silver" />
        </visual>
        <collision>
            <origin rpy="0 0 0" xyz="0.636621 0.008451 -0.647445" />
            <geometry>
                <mesh filename="package://robotic_arm_description/meshes/jaw7.2_1.stl" scale="0.001 0.001 0.001" />
            </geometry>
        </collision>
    </link>
    <joint name="Revolute_12" type="revolute">
        <origin rpy="0 0 0" xyz="0.000534 0.058358 0.084193" />
        <parent link="base_link" />
        <child link="jaw1_1" />
        <axis xyz="-0.0 -0.0 -1.0" />
        <limit effort="100" lower="0.0" upper="6.283185" velocity="100" />
    </joint>
    <joint name="Revolute_13" type="revolute">
        <origin rpy="0 0 0" xyz="-0.15 0.02 0.16" />
        <parent link="jaw1_1" />
        <child link="jaw2_1" />
        <axis xyz="-0.0 -1.0 -0.0" />
        <limit effort="100" lower="-1.047198" upper="1.570796" velocity="100" />
    </joint>
    <joint name="Revolute_14" type="revolute">
        <origin rpy="0 0 0" xyz="0.0 0.0 0.35" />
        <parent link="jaw2_1" />
        <child link="jaw3_1" />
        <axis xyz="0.0 1.0 0.0" />
        <limit effort="100" lower="-0.523599" upper="3.141593" velocity="100" />
    </joint>
    <joint name="Revolute_15" type="revolute">
        <origin rpy="0 0 0" xyz="-0.246263 -0.048 0.044252" />
        <parent link="jaw3_1" />
        <child link="jaw4_1" />
        <axis xyz="1.0 -0.0 0.0" />
        <limit effort="100" lower="0.0" upper="3.141593" velocity="100" />
    </joint>
    <joint name="Revolute_16" type="revolute">
        <origin rpy="0 0 0" xyz="-0.115 0.0125 0.0" />
        <parent link="jaw4_1" />
        <child link="jaw5_1" />
        <axis xyz="0.0 1.0 0.0" />
        <limit effort="100" lower="-1.745329" upper="1.745329" velocity="100" />
    </joint>
    <joint name="Revolute_17" type="revolute">
        <origin rpy="0 0 0" xyz="-0.093 -0.012 0.0" />
        <parent link="jaw5_1" />
        <child link="jaw6_1" />
        <axis xyz="1.0 0.0 0.0" />
        <limit effort="100" lower="0.0" upper="3.141593" velocity="100" />
    </joint>
    <joint name="Revolute_22" type="revolute">
        <origin rpy="0 0 0" xyz="-0.032892 0.03931 0.009" />
        <parent link="jaw6_1" />
        <child link="jaw7.1_1" />
        <axis xyz="-0.0 0.0 1.0" />
        <limit effort="100" lower="-1.570796" upper="0.292343" velocity="100" />
    </joint>
    <joint name="Revolute_24" type="revolute">
        <origin rpy="0 0 0" xyz="-0.032892 -0.039309 0.009" />
        <parent link="jaw6_1" />
        <child link="jaw7.2_1" />
        <axis xyz="-0.0 0.0 1.0" />
        <limit effort="100" lower="-0.292343" upper="1.570796" velocity="100" />
    </joint>
</robot>

